File: tungsten1.raw
"Test Type","Manual"
"Method Name:","C:\INSTRON\user\template\245L-Mod01.mtM"
"Name:","4FtPerMin"
"Operator ID:","Jaques"
"Company:","BSU"
"Lab name:",""
"Test date:","1/26/15"
"Temperature:",""
"Humidity:",""
"Note 1:",""
"Note 2:",""
"Note 3:",""
"Geometry:","Circular"
"Specimen",1
"Specimen name:",""
"Width:",6.350000,"mm"
"Thickness:",1.524000,"mm"
"Length:",12.000000,"mm"
"Diameter:",5.000000,"um"
"Inner diameter:",0.500000,"mm"
"Outer diameter:",1.000000,"mm"
"Wall thickness:",0.500000,"mm"
"Area:",19.634954,"um*um"
"Linear density:",1.000000,"den"
"Sled weight:",9.806650,"N"
"Loading span:",0.000000,"mm"
"Support span:",1.000000,"mm"
"Span ratio:","2"
"Fixture type:","3-point"
"Comment:",""
"Included"
"Time sec","Extension mm","Load N","Stress MPa","Cycle Count ","Total Cycle Count ","Repetitions Count ","Strain [Exten.] %","Tenacity gf/tex"
0,0,-5.158131,-262701.5,0,0,0,0,-4733.847
0.004,0,-5.168628,-263236.1,0,0,0,0,-4743.48
0.008,0,-5.18056,-263843.8,0,0,0,0,-4754.431
0.012,0,-5.19215,-264434,0,0,0,0,-4765.067
0.016,0,-5.202673,-264970,0,0,0,0,-4774.725
0.036,0,-5.188265,-264236.2,0,0,0,0,-4761.502
0.04,0,-5.175682,-263595.3,0,0,0,0,-4749.955
0.044,0,-5.161156,-262855.5,0,0,0,0,-4736.623
0.048,0,-5.145434,-262054.8,0,0,0,0,-4722.194
0.052,0,-5.131649,-261352.8,0,0,0,0,-4709.543
0.058,0,-5.117828,-260648.8,0,0,0,0,-4696.859
0.064,0,-5.105846,-260038.6,0,0,0,0,-4685.863
0.072,0,-5.09447,-259459.3,0,0,0,0,-4675.423
0.084,0,-5.108316,-260164.4,0,0,0,0,-4688.129
0.088,0,-5.120175,-260768.4,0,0,0,0,-4699.013
0.092,0,-5.136215,-261585.3,0,0,0,0,-4713.733
0.096,0,-5.154797,-262531.7,0,0,0,0,-4730.788
0.1,0,-5.172963,-263456.9,0,0,0,0,-4747.459