File: tungsten2.raw
"Specimen",2
"Specimen name:",""
"Width:",6.350000,"mm"
"Thickness:",1.524000,"mm"
"Length:",12.000000,"mm"
"Diameter:",5.000000,"um"
"Inner diameter:",0.500000,"mm"
"Outer diameter:",1.000000,"mm"
"Wall thickness:",0.500000,"mm"
"Area:",19.634954,"um*um"
"Linear density:",1.000000,"den"
"Sled weight:",9.806650,"N"
"Loading span:",0.000000,"mm"
"Support span:",1.000000,"mm"
"Span ratio:","2"
"Fixture type:","3-point"
"Comment:",""
"Included"
"Time sec","Extension mm","Load N","Stress MPa","Cycle Count ","Total Cycle Count ","Repetitions Count ","Strain [Exten.] %","Tenacity gf/tex"
0,-0.7815275,-4.753184,-242077.7,0,0,0,-6.512729,-4362.209
0.028,-0.7815275,-4.743083,-241563.2,0,0,0,-6.512729,-4352.938
0.042,-0.7815275,-4.732641,-241031.4,0,0,0,-6.512729,-4343.355
0.132,-0.7815275,-4.720662,-240421.4,0,0,0,-6.512729,-4332.362
0.144,-0.7815275,-4.710006,-239878.6,0,0,0,-6.512729,-4322.583
0.156,-0.7815275,-4.723286,-240555,0,0,0,-6.512729,-4334.77
0.162,-0.7815275,-4.737962,-241302.4,0,0,0,-6.512729,-4348.239
0.166,-0.7815275,-4.748001,-241813.7,0,0,0,-6.512729,-4357.452
0.172,-0.7815275,-4.760344,-242442.3,0,0,0,-6.512729,-4368.78
0.178,-0.7819996,-4.766881,-242775.3,0,0,0,-6.516664,-4374.779
0.204,-0.7819996,-4.777556,-243319,0,0,0,-6.516664,-4384.577
0.232,-0.7819996,-4.766494,-242755.5,0,0,0,-6.516664,-4374.424
0.236,-0.7822358,-4.764415,-242649.7,0,0,0,-6.518631,-4372.517
0.248,-0.7822358,-4.777575,-243319.9,0,0,0,-6.518631,-4384.594
0.254,-0.7822358,-4.790792,-243993,0,0,0,-6.518631,-4396.724
0.26,-0.7822358,-4.805217,-244727.7,0,0,0,-6.518631,-4409.961
0.264,-0.7822358,-4.815225,-245237.4,0,0,0,-6.518631,-4419.146
0.27,-0.7822358,-4.829271,-245952.8,0,0,0,-6.518631,-4432.037
0.276,-0.7822358,-4.843385,-246671.6,0,0,0,-6.518631,-4444.99
0.278,-0.7824719,-4.848299,-246921.8,0,0,0,-6.520599,-4449.5
0.282,-0.7824719,-4.858729,-247453,0,0,0,-6.520599,-4459.072
0.286,-0.7824719,-4.870162,-248035.3,0,0,0,-6.520599,-4469.565
0.29,-0.7824719,-4.883844,-248732.1,0,0,0,-6.520599,-4482.122
0.294,-0.7824719,-4.899069,-249507.5,0,0,0,-6.520599,-4496.094
0.298,-0.7824719,-4.913263,-250230.5,0,0,0,-6.520599,-4509.121
0.302,-0.7824719,-4.923671,-250760.5,0,0,0,-6.520599,-4518.673
0.314,-0.782708,-4.933883,-251280.6,0,0,0,-6.522567,-4528.044
0.344,-0.7829441,-4.930009,-251083.3,0,0,0,-6.524534,-4524.489
0.352,-0.7829441,-4.941837,-251685.7,0,0,0,-6.524534,-4535.345
0.358,-0.7829441,-4.957067,-252461.4,0,0,0,-6.524534,-4549.322
0.362,-0.7829441,-4.968492,-253043.2,0,0,0,-6.524534,-4559.807