File: tungsten3.raw
"Specimen",3
"Specimen name:",""
"Width:",6.350000,"mm"
"Thickness:",1.524000,"mm"
"Length:",12.000000,"mm"
"Diameter:",5.000000,"um"
"Inner diameter:",0.500000,"mm"
"Outer diameter:",1.000000,"mm"
"Wall thickness:",0.500000,"mm"
"Area:",19.634954,"um*um"
"Linear density:",1.000000,"den"
"Sled weight:",9.806650,"N"
"Loading span:",0.000000,"mm"
"Support span:",1.000000,"mm"
"Span ratio:","2"
"Fixture type:","3-point"
"Comment:",""
"Included"
"Time sec","Extension mm","Load N","Stress MPa","Cycle Count ","Total Cycle Count ","Repetitions Count ","Strain [Exten.] %","Tenacity gf/tex"
0,0,-4.965317,-252881.5,0,0,0,0,-4556.893
0.006,0,-4.979633,-253610.6,0,0,0,0,-4570.031
0.01,0,-4.992541,-254268,0,0,0,0,-4581.877
0.014,0,-5.007477,-255028.7,0,0,0,0,-4595.585
0.018,0,-5.024315,-255886.3,0,0,0,0,-4611.038
0.022,0,-5.042806,-256828,0,0,0,0,-4628.008
0.026,0,-5.061555,-257782.9,0,0,0,0,-4645.215
0.03,0,-5.079649,-258704.4,0,0,0,0,-4661.82
0.034,0,-5.093854,-259427.9,0,0,0,0,-4674.857
0.052,0,-5.076984,-258568.7,0,0,0,0,-4659.375
0.056,0,-5.058025,-257603.1,0,0,0,0,-4641.975
0.058,0,-5.047471,-257065.6,0,0,0,0,-4632.289
0.06,0,-5.036524,-256508.1,0,0,0,0,-4622.243
0.062,0,-5.025493,-255946.2,0,0,0,0,-4612.119
0.064,0,-5.014709,-255397,0,0,0,0,-4602.222
0.066,0,-5.004569,-254880.6,0,0,0,0,-4592.917
0.07,0,-4.987599,-254016.3,0,0,0,0,-4577.342
0.074,0,-4.975278,-253388.8,0,0,0,0,-4566.034
0.08,0,-4.962629,-252744.6,0,0,0,0,-4554.426
0.09,0,-4.951861,-252196.2,0,0,0,0,-4544.543
0.108,0,-4.965908,-252911.6,0,0,0,0,-4557.435
0.112,0,-4.981194,-253690.1,0,0,0,0,-4571.463
0.116,0,-5.002089,-254754.3,0,0,0,0,-4590.641
0.118,0,-5.013986,-255360.2,0,0,0,0,-4601.558
0.12,0,-5.026184,-255981.5,0,0,0,0,-4612.753
0.122,0,-5.03837,-256602.1,0,0,0,0,-4623.937
0.124,0,-5.050465,-257218.1,0,0,0,0,-4635.037
0.126,0,-5.062334,-257822.6,0,0,0,0,-4645.93
0.128,0,-5.073515,-258392,0,0,0,0,-4656.191
0.132,0,-5.091375,-259301.6,0,0,0,0,-4672.582
0.136,0,-5.10197,-259841.2,0,0,0,0,-4682.305